Workbook

Sheet 00 Cover
A1: RMM 2026 HEAVY CIVIL BENCHMARK MASTER - Canada-Wide Unit Rates with Multi-Source Comparison
A2: Prepared for Ausenco / NexGold Goldboro FS 2026 benchmarking and bidder vetting. Single self-contained reference document.
A4: AUTHOR | B4: Rick Miller, Senior Project Director / EPCM
A5: DOCUMENT | B5: RMM-BENCHMARK-CANADA-2026-V3
A6: ISSUE DATE | B6: Q2 2026
A7: BASE YEAR / CCY | B7: Q2 2026 / Canadian Dollars (CAD)
A8: PREPARED FOR | B8: Ausenco Engineering Canada / NexGold Mining Corp. - Goldboro FS 2026 civil benchmark vetting and bidder submission evaluation. Shared internally with Carter's Mechanical Consulting principal as engagement reference.
A9: CONFIDENTIALITY | B9: Internal working document. Confidential and proprietary. Bidder pricing references are subject to the Goldboro C5027 tender confidentiality terms. Not for redistribution outside Ausenco / NexGold / Carter's principal.
A10: PURPOSE | B10: Single self-contained 2026 heavy civil benchmark for: (a) issuing to bidders alongside tender packages as the reference market data; (b) back-pressuring out-of-range bidder submissions ('your culvert rate is 2× the NS market median, please explain'); (c) handing to owner / EPCM (Ausenco, NexGold) as defensible internal estimating standard; (d) cross-calibrating own estimates against multiple real 2026 data points.
A11: WHAT MAKES THIS DEFENSIBLE | B11: Every line item carries up to 6 cross-referenced data points: (1) Author SME range by region (Canada-wide, 7 regions); (2) GHD Goldboro 2026 vendor-quoted real-print pricing (Atlantic NS anchor; from GHD project file Apr 14, 2026); (3) Alberta Transportation 2026 UPA (highway tender baseline, weighted avg of 3 low bids May 2024 – Sep 2025, public data); (4) Rick Miller Q2 2026 operator intel (tandem $150/hr; wiggle wagon $200/hr; crushing 'through the roof'); (5) Goldboro C5027 5-bidder April 2026 submissions (Bird, Dexter, GIP, Greenfields, Nova - real contractor market); (6) Statistics Canada Q1 2026 BCPI (+3.6% YoY non-residential macro context).
A12: STRUCTURE | B12: 9 tabs total: 00 Cover - 01 Rate Schedule (unit-rate master with regional ranges, anchors, bidder submissions, operational deltas + flags) - 02 Equipment Rates (hourly equipment by region) - 03 Regional Adjustors - 04 Vetting Workflow - 05 Sources and Methodology - 06 Coverage Summary - 07 Project Pricing (operational rollup) - 08 Data Integrity QC
A13: COVERAGE - SCOPE | B13: 180 canonical scope unit rate items across 25 sections (A-Y) covering end-to-end mining heavy civil: earthworks, water mgmt, roads, WRSA/TMF, drainage, concrete, steel, closure, blasting, dewatering, buried services, fencing, signage, rock anchors, culvert structures, crushing, underground civil, tailings dam zoned, heap leach pads, process plant civil, slurry pipelines, mine bridges, power line civil, hydraulic structures.
A14: COVERAGE - EQUIPMENT | B14: Tab '02 Equipment Rates' carries 30 equipment hourly rates (trucks, excavators, dozers, graders, compactors, loaders, drills, cranes, pumps) with the same regional cross-reference + Rick Q2 2026 intel anchors for tandem ($150/hr) and 45T wiggle wagon ($200/hr).
A15: COVERAGE - REGIONAL | B15: 7 Canadian regions: NL / NS / ON / MB-SK / AB / BC / YT-NWT. Base SME range adjusted by published regional factor (per Sheet 03).
... A19: LIMITATIONS | B19: Specialty mining sections (Underground / Bridges / Power Line / Hydraulic - sections R, W, X, Y) carry SME-only ranges because public market benchmark data does not exist for these scopes in Canada. Flagged as LOW confidence on Sheet 06. Validate against project-specific RFQ for Class 2/1 estimates.

Sheet 01 Rate Schedule
A1: RMM 2026 HEAVY CIVIL BENCHMARK MASTER - Rate Schedule (Canada-wide, GHD-style layout)
A2: Atlantic GREEN / Central PURPLE / Western ORANGE / Northern BROWN. Anchors GOLD. Bidder submissions RED. RECOMMENDED YELLOW.
A3: IDENTIFICATION | E3: ATLANTIC (NL / NS) | I3: CENTRAL (ON / MB-SK) | M3: WESTERN (AB / BC) | Q3: NORTHERN (YT/NWT/NU) | S3: REFERENCE ANCHORS (Real 2026) | V3: C5027 BIDDER SUBMISSIONS — Individual Rates (Apr 2026) | AA3: BIDDER STATS (per-rate) | AE3: RMM RECOMMENDED 2026 | AF3: VETTING / MATCH BASIS | AH3: BIDDER MED Δ% | AI3: GHD Δ% | AJ3: FLAG
A4: WBS L4 | B4: Code | C4: Description / Scope | D4: UOM | E4: NL Low | F4: NL High | G4: NS Low | H4: NS High | I4: ON Low | J4: ON High | K4: MB/SK Low | L4: MB/SK High | M4: AB Low | N4: AB High | O4: BC Low | P4: BC High | Q4: YT/NWT Low | R4: YT/NWT High | S4: GHD Goldboro 2026 | T4: AB UPA 2026 | U4: Rick Anchor | V4: Bird | W4: Dexter | X4: GIP | Y4: Greenfields | Z4: Nova | AA4: Bidder Min | AB4: Bidder Med | AC4: Bidder Max | AD4: Spread % | AE4: 2026 $ / UOM | AF4: Vetting Note | AG4: Match Basis | AH4: Bidder Med vs REC | AI4: GHD vs REC | AJ4: FLAG
A5: A. Earthworks
B6: C-10-004 | C6: Backfill Type 1 (<250mm) - spread and compact | D6: m3 | E6: 37 | F6: 55 | G6: 35 | H6: 53 | I6: 41 | J6: 61 | K6: 40 | L6: 56 | M6: 42 | N6: 70 | O6: 44 | P6: 68 | Q6: 52 | R6: 81 | S6: 85 | T6: - | U6: - | V6: 66.45 | W6: 51.94 | X6: 15.54 | Y6: 12.44 | Z6: 40 | AA6: =MIN(V6:Z6) | AB6: =MEDIAN(V6:Z6) | AC6: =MAX(V6:Z6) | AD6: =IFERROR((AC6-AA6)/AB6,"—") | AE6: =AVERAGE(G6,H6) | AF6: OK — sources align | AG6: keyword-matched | AH6: =IFERROR((AB6-AE6)/AE6,"—") | AI6: =IFERROR((S6-AE6)/AE6,"—") | AJ6: =IF(AD6>1, "⚠ HIGH SPREAD", IF(ABS(AH6)>0.5, "⚠ DELTA", "OK"))
B7: C-10-005 | C7: Backfill Type 2 (<100mm) - spread and compact | D7: m3 | E7: 51 | F7: 71 | G7: 48 | H7: 69 | I7: 56 | J7: 80 | K7: 55 | L7: 73 | M7: 58 | N7: 92 | O7: 61 | P7: 88 | Q7: 72 | R7: 105 | S7: 85 | T7: - | U7: - | V7: 66.45 | W7: 51.94 | X7: 15.54 | Y7: 12.44 | Z7: 40 | AA7: =MIN(V7:Z7) | AB7: =MEDIAN(V7:Z7) | AC7: =MAX(V7:Z7) | AD7: =IFERROR((AC7-AA7)/AB7,"—") | AE7: =AVERAGE(G7,H7) | AF7: OK — sources align | AG7: keyword-matched | AH7: =IFERROR((AB7-AE7)/AE7,"—") | AI7: =IFERROR((S7-AE7)/AE7,"—") | AJ7: =IF(AD7>1, "⚠ HIGH SPREAD", IF(ABS(AH7)>0.5, "⚠ DELTA", "OK"))
B8: C-10-006 | C8: Backfill Type 3 engineered - spread and compact | D8: m3 | E8: 66 | F8: 92 | G8: 63 | H8: 90 | I8: 73 | J8: 104 | K8: 72 | L8: 95 | M8: 76 | N8: 119 | O8: 79 | P8: 114 | Q8: 94 | R8: 136 | S8: 85 | T8: - | U8: - | V8: 66.45 | W8: 51.94 | X8: 15.54 | Y8: 12.44 | Z8: 40 | AA8: =MIN(V8:Z8) | AB8: =MEDIAN(V8:Z8) | AC8: =MAX(V8:Z8) | AD8: =IFERROR((AC8-AA8)/AB8,"—") | AE8: =AVERAGE(G8,H8) | AF8: OK — sources align | AG8: keyword-matched | AH8: =IFERROR((AB8-AE8)/AE8,"—") | AI8: =IFERROR((S8-AE8)/AE8,"—") | AJ8: =IF(AD8>1, "⚠ HIGH SPREAD", IF(ABS(AH8)>0.5, "⚠ DELTA", "OK"))
B9: C-10-003 | C9: Backfill common - spread and compact | D9: m3 | E9: 20 | F9: 29 | G9: 19 | H9: 29 | I9: 22 | J9: 33 | K9: 22 | L9: 30 | M9: 23 | N9: 38 | O9: 24 | P9: 36 | Q9: 29 | R9: 43 | S9: 85 | T9: 15.22 | U9: - | V9: 66.45 | W9: 51.94 | X9: 15.54 | Y9: 12.44 | Z9: 40 | AA9: =MIN(V9:Z9) | AB9: =MEDIAN(V9:Z9) | AC9: =MAX(V9:Z9) | AD9: =IFERROR((AC9-AA9)/AB9,"—") | AE9: =AVERAGE(G9,H9) | AF9: OK — sources align | AG9: keyword-matched | AH9: =IFERROR((AB9-AE9)/AE9,"—") | AI9: =IFERROR((S9-AE9)/AE9,"—") | AJ9: =IF(AD9>1, "⚠ HIGH SPREAD", IF(ABS(AH9)>0.5, "⚠ DELTA", "OK"))
B10: C-10-014 | C10: Cut-fill balanced earthworks - large-scale | D10: m3 | E10: 20 | F10: 32 | G10: 19 | H10: 31 | I10: 22 | J10: 35 | K10: 22 | L10: 32 | M10: 23 | N10: 40 | O10: 24 | P10: 39 | Q10: 29 | R10: 46 | S10: - | T10: - | U10: - | V10: 30.15 | W10: 51.94 | X10: 40.39 | Y10: 26.47 | Z10: 25 | AA10: =MIN(V10:Z10) | AB10: =MEDIAN(V10:Z10) | AC10: =MAX(V10:Z10) | AD10: =IFERROR((AC10-AA10)/AB10,"—") | AE10: =AVERAGE(G10,H10) | AF10: OK — sources align | AG10: category-fallback | AH10: =IFERROR((AB10-AE10)/AE10,"—") | AI10: =IFERROR((S10-AE10)/AE10,"—") | AJ10: =IF(AD10>1, "⚠ HIGH SPREAD", IF(ABS(AH10)>0.5, "⚠ DELTA", "OK"))
B11: C-10-016 | C11: Drill and blast holes only - excavation separate | D11: m3 | E11: 39 | F11: 68 | G11: 37 | H11: 66 | I11: 43 | J11: 77 | K11: 42 | L11: 70 | M11: 44 | N11: 88 | O11: 46 | P11: 84 | Q11: 55 | R11: 101 | S11: 14800 | T11: - | U11: - | V11: 5.7 | W11: 13.98 | X11: 8.92 | Y11: 10.7 | Z11: 27.5 | AA11: =MIN(V11:Z11) | AB11: =MEDIAN(V11:Z11) | AC11: =MAX(V11:Z11) | AD11: =IFERROR((AC11-AA11)/AB11,"—") | AE11: =AVERAGE(G11,H11) | AF11: OK — sources align | AG11: category-fallback; keyword-matched | AH11: =IFERROR((AB11-AE11)/AE11,"—") | AI11: =IFERROR((S11-AE11)/AE11,"—") | AJ11: =IF(AD11>1, "⚠ HIGH SPREAD", IF(ABS(AH11)>0.5, "⚠ DELTA", "OK"))
B12: C-10-002 | C12: Excavation common soil - load + haul 1-3 km | D12: m3 | E12: 22 | F12: 34 | G12: 21 | H12: 33 | I12: 24 | J12: 38 | K12: 24 | L12: 35 | M12: 25 | N12: 43 | O12: 26 | P12: 42 | Q12: 31 | R12: 50 | S12: 26 | T12: 8.2 | U12: - | V12: 51.65 | W12: 19.12 | X12: 11.42 | Y12: 12.44 | Z12: 70 | AA12: =MIN(V12:Z12) | AB12: =MEDIAN(V12:Z12) | AC12: =MAX(V12:Z12) | AD12: =IFERROR((AC12-AA12)/AB12,"—") | AE12: =AVERAGE(G12,H12) | AF12: OK — sources align | AG12: keyword-matched | AH12: =IFERROR((AB12-AE12)/AE12,"—") | AI12: =IFERROR((S12-AE12)/AE12,"—") | AJ12: =IF(AD12>1, "⚠ HIGH SPREAD", IF(ABS(AH12)>0.5, "⚠ DELTA", "OK"))
B13: C-10-009 | C13: Granular A base (<19mm) - supply+place+compact | D13: m3 | E13: 97 | F13: 142 | G13: 92 | H13: 138 | I13: 107 | J13: 159 | K13: 105 | L13: 146 | M13: 110 | N13: 182 | O13: 116 | P13: 176 | Q13: 136 | R13: 209 | S13: 50 | T13: 34.27 | U13: - | V13: 116 | W13: 51.94 | X13: 36.72 | Y13: 12.44 | Z13: 70 | AA13: =MIN(V13:Z13) | AB13: =MEDIAN(V13:Z13) | AC13: =MAX(V13:Z13) | AD13: =IFERROR((AC13-AA13)/AB13,"—") | AE13: =AVERAGE(G13,H13) | AF13: OK — sources align | AG13: keyword-matched | AH13: =IFERROR((AB13-AE13)/AE13,"—") | AI13: =IFERROR((S13-AE13)/AE13,"—") | AJ13: =IF(AD13>1, "⚠ HIGH SPREAD", IF(ABS(AH13)>0.5, "⚠ DELTA", "OK"))
B14: C-10-010 | C14: Granular B sub-base (<75mm) - supply+place+compact | D14: m3 | E14: 81 | F14: 121 | G14: 77 | H14: 117 | I14: 90 | J14: 136 | K14: 88 | L14: 124 | M14: 92 | N14: 155 | O14: 97 | P14: 150 | Q14: 114 | R14: 178 | S14: 50 | T14: - | U14: - | V14: 50.85 | W14: 61.02 | X14: 27.51 | Y14: 12.44 | Z14: 40 | AA14: =MIN(V14:Z14) | AB14: =MEDIAN(V14:Z14) | AC14: =MAX(V14:Z14) | AD14: =IFERROR((AC14-AA14)/AB14,"—") | AE14: =AVERAGE(G14,H14) | AF14: OK — sources align | AG14: size-matched | AH14: =IFERROR((AB14-AE14)/AE14,"—") | AI14: =IFERROR((S14-AE14)/AE14,"—") | AJ14: =IF(AD14>1, "⚠ HIGH SPREAD", IF(ABS(AH14)>0.5, "⚠ DELTA", "OK"))
B15: C-10-008 | C15: Overburden strip - doze + rip + stockpile | D15: m3 | E15: 17 | F15: 29 | G15: 16 | H15: 29 | I15: 18 | J15: 33 | K15: 18 | L15: 30 | M15: 19 | N15: 38 | O15: 20 | P15: 36 | Q15: 23 | R15: 43 | S15: - | T15: - | U15: - | V15: 30.15 | W15: 17.2 | X15: 8.79 | Y15: 26.47 | Z15: 15 | AA15: =MIN(V15:Z15) | AB15: =MEDIAN(V15:Z15) | AC15: =MAX(V15:Z15) | AD15: =IFERROR((AC15-AA15)/AB15,"—") | AE15: =AVERAGE(G15,H15) | AF15: OK — sources align | AG15: category-fallback | AH15: =IFERROR((AB15-AE15)/AE15,"—") | AI15: =IFERROR((S15-AE15)/AE15,"—") | AJ15: =IF(AD15>1, "⚠ HIGH SPREAD", IF(ABS(AH15)>0.5, "⚠ DELTA", "OK"))
B16: C-10-007 | C16: Rock excavation - blasted and loaded to truck | D16: m3 | E16: 35 | F16: 61 | G16: 33 | H16: 59 | I16: 39 | J16: 68 | K16: 38 | L16: 63 | M16: 40 | N16: 78 | O16: 42 | P16: 75 | Q16: 49 | R16: 90 | S16: - | T16: - | U16: - | V16: 8.75 | W16: 16.34 | X16: 19.39 | Y16: 10.3 | Z16: 13.5 | AA16: =MIN(V16:Z16) | AB16: =MEDIAN(V16:Z16) | AC16: =MAX(V16:Z16) | AD16: =IFERROR((AC16-AA16)/AB16,"—") | AE16: =AVERAGE(G16,H16) | AF16: OK — sources align | AG16: keyword-matched | AH16: =IFERROR((AB16-AE16)/AE16,"—") | AI16: =IFERROR((S16-AE16)/AE16,"—") | AJ16: =IF(AD16>1, "⚠ HIGH SPREAD", IF(ABS(AH16)>0.5, "⚠ DELTA", "OK"))
B17: C-10-011 | C17: Sand bedding layer - supply+place+compact | D17: m3 | E17: 106 | F17: 152 | G17: 101 | H17: 148 | I17: 117 | J17: 171 | K17: 115 | L17: 157 | M17: 121 | N17: 196 | O17: 127 | P17: 188 | Q17: 150 | R17: 225 | S17: 91.034 | T17: - | U17: - | V17: 116 | W17: 51.94 | X17: 36.72 | Y17: 12.44 | Z17: 70 | AA17: =MIN(V17:Z17) | AB17: =MEDIAN(V17:Z17) | AC17: =MAX(V17:Z17) | AD17: =IFERROR((AC17-AA17)/AB17,"—") | AE17: =AVERAGE(G17,H17) | AF17: OK — sources align | AG17: keyword-matched | AH17: =IFERROR((AB17-AE17)/AE17,"—") | AI17: =IFERROR((S17-AE17)/AE17,"—") | AJ17: =IF(AD17>1, "⚠ HIGH SPREAD", IF(ABS(AH17)>0.5, "⚠ DELTA", "OK"))
B18: C-10-013 | C18: Seeding and restoration - hydraulic | D18: m2 | E18: 4 | F18: 8 | G18: 4 | H18: 8 | I18: 4 | J18: 9 | K18: 4 | L18: 9 | M18: 4 | N18: 11 | O18: 4 | P18: 10 | Q18: 5 | R18: 12 | S18: - | T18: - | U18: - | V18: 11.1 | W18: — | X18: 14.54 | Y18: — | Z18: 5 | AA18: =MIN(V18:Z18) | AB18: =MEDIAN(V18:Z18) | AC18: =MAX(V18:Z18) | AD18: =IFERROR((AC18-AA18)/AB18,"—") | AE18: =AVERAGE(G18,H18) | AF18: OK — sources align | AG18: category-fallback | AH18: =IFERROR((AB18-AE18)/AE18,"—") | AI18: =IFERROR((S18-AE18)/AE18,"—") | AJ18: =IF(AD18>1, "⚠ HIGH SPREAD", IF(ABS(AH18)>0.5, "⚠ DELTA", "OK"))
B19: C-10-015 | C19: Settling pond / water management excavation | D19: m3 | E19: 20 | F19: 29 | G19: 19 | H19: 29 | I19: 22 | J19: 33 | K19: 22 | L19: 30 | M19: 23 | N19: 38 | O19: 24 | P19: 36 | Q19: 29 | R19: 43 | S19: 2.47 | T19: - | U19: - | V19: 9.95 | W19: 14.4 | X19: 45.33 | Y19: 10.7 | Z19: 9.5 | AA19: =MIN(V19:Z19) | AB19: =MEDIAN(V19:Z19) | AC19: =MAX(V19:Z19) | AD19: =IFERROR((AC19-AA19)/AB19,"—") | AE19: =AVERAGE(G19,H19) | AF19: OK — sources align | AG19: keyword-matched | AH19: =IFERROR((AB19-AE19)/AE19,"—") | AI19: =IFERROR((S19-AE19)/AE19,"—") | AJ19: =IF(AD19>1, "⚠ HIGH SPREAD", IF(ABS(AH19)>0.5, "⚠ DELTA", "OK"))
B20: C-10-012 | C20: Topsoil placement - supply+spread | D20: m3 | E20: 51 | F20: 84 | G20: 48 | H20: 82 | I20: 56 | J20: 94 | K20: 55 | L20: 86 | M20: 58 | N20: 108 | O20: 61 | P20: 104 | Q20: 72 | R20: 124 | S20: 10 | T20: - | U20: - | V20: 13.95 | W20: 49.78 | X20: 9.68 | Y20: 12.44 | Z20: 15 | AA20: =MIN(V20:Z20) | AB20: =MEDIAN(V20:Z20) | AC20: =MAX(V20:Z20) | AD20: =IFERROR((AC20-AA20)/AB20,"—") | AE20: =AVERAGE(G20,H20) | AF20: OK — sources align | AG20: keyword-matched | AH20: =IFERROR((AB20-AE20)/AE20,"—") | AI20: =IFERROR((S20-AE20)/AE20,"—") | AJ20: =IF(AD20>1, "⚠ HIGH SPREAD", IF(ABS(AH20)>0.5, "⚠ DELTA", "OK"))
A21: B. Water Mgmt
B22: C-20-005 | C22: Energy dissipator riprap - full S+P | D22: m3 | E22: 110 | F22: 210 | G22: 106 | H22: 204 | I22: 122 | J22: 236 | K22: 120 | L22: 216 | M22: 126 | N22: 270 | O22: 132 | P22: 260 | Q22: 156 | R22: 310 | S22: 19.657 | T22: - | U22: - | V22: 66.45 | W22: 70.1 | X22: 45.33 | Y22: 9.42 | Z22: 60 | AA22: =MIN(V22:Z22) | AB22: =MEDIAN(V22:Z22) | AC22: =MAX(V22:Z22) | AD22: =IFERROR((AC22-AA22)/AB22,"—") | AE22: =AVERAGE(G22,H22) | AF22: OK — sources align | AG22: keyword-matched | AH22: =IFERROR((AB22-AE22)/AE22,"—") | AI22: =IFERROR((S22-AE22)/AE22,"—") | AJ22: =IF(AD22>1, "⚠ HIGH SPREAD", IF(ABS(AH22)>0.5, "⚠ DELTA", "OK"))
B23: C-20-006 | C23: Geotextile 10oz non-woven cushion - S+I | D23: m2 | E23: 4 | F23: 9 | G23: 4 | H23: 9 | I23: 4 | J23: 11 | K23: 4 | L23: 10 | M23: 4 | N23: 12 | O23: 4 | P23: 12 | Q23: 5 | R23: 14 | S23: 6 | T23: - | U23: - | V23: 16.6 | W23: 5.68 | X23: 10.86 | Y23: 1.4 | Z23: 5 | AA23: =MIN(V23:Z23) | AB23: =MEDIAN(V23:Z23) | AC23: =MAX(V23:Z23) | AD23: =IFERROR((AC23-AA23)/AB23,"—") | AE23: =AVERAGE(G23,H23) | AF23: OK — sources align | AG23: size-matched | AH23: =IFERROR((AB23-AE23)/AE23,"—") | AI23: =IFERROR((S23-AE23)/AE23,"—") | AJ23: =IF(AD23>1, "⚠ HIGH SPREAD", IF(ABS(AH23)>0.5, "⚠ DELTA", "OK"))
B24: C-20-007 | C24: Geotextile 6oz non-woven separator - S+I | D24: m2 | E24: 3 | F24: 6 | G24: 3 | H24: 6 | I24: 3 | J24: 7 | K24: 3 | L24: 6 | M24: 3 | N24: 8 | O24: 3 | P24: 8 | Q24: 4 | R24: 9 | S24: 6 | T24: 2.82 | U24: - | V24: 16.6 | W24: 5.68 | X24: 10.86 | Y24: 1.4 | Z24: 5 | AA24: =MIN(V24:Z24) | AB24: =MEDIAN(V24:Z24) | AC24: =MAX(V24:Z24) | AD24: =IFERROR((AC24-AA24)/AB24,"—") | AE24: =AVERAGE(G24,H24) | AF24: OK — sources align | AG24: keyword-matched | AH24: =IFERROR((AB24-AE24)/AE24,"—") | AI24: =IFERROR((S24-AE24)/AE24,"—") | AJ24: =IF(AD24>1, "⚠ HIGH SPREAD", IF(ABS(AH24)>0.5, "⚠ DELTA", "OK"))
B25: C-20-002 | C25: Riprap D50 150mm entrance/exit - supply+place | D25: m3 | E25: 60 | F25: 105 | G25: 57 | H25: 102 | I25: 66 | J25: 118 | K25: 65 | L25: 108 | M25: 68 | N25: 135 | O25: 72 | P25: 130 | Q25: 84 | R25: 155 | S25: 19.657 | T25: 313.41 | U25: - | V25: 66.45 | W25: 70.1 | X25: 45.33 | Y25: 12.44 | Z25: 40 | AA25: =MIN(V25:Z25) | AB25: =MEDIAN(V25:Z25) | AC25: =MAX(V25:Z25) | AD25: =IFERROR((AC25-AA25)/AB25,"—") | AE25: =AVERAGE(G25,H25) | AF25: OK — sources align | AG25: size-matched | AH25: =IFERROR((AB25-AE25)/AE25,"—") | AI25: =IFERROR((S25-AE25)/AE25,"—") | AJ25: =IF(AD25>1, "⚠ HIGH SPREAD", IF(ABS(AH25)>0.5, "⚠ DELTA", "OK"))
B26: C-20-003 | C26: Riprap D50 300mm - supply+place | D26: m3 | E26: 69 | F26: 126 | G26: 66 | H26: 122 | I26: 76 | J26: 142 | K26: 75 | L26: 130 | M26: 79 | N26: 162 | O26: 82 | P26: 156 | Q26: 98 | R26: 186 | S26: - | T26: 265.82 | U26: - | V26: 35.25 | W26: 51.94 | X26: 11.42 | Y26: 12.44 | Z26: 40 | AA26: =MIN(V26:Z26) | AB26: =MEDIAN(V26:Z26) | AC26: =MAX(V26:Z26) | AD26: =IFERROR((AC26-AA26)/AB26,"—") | AE26: =AVERAGE(G26,H26) | AF26: OK — sources align | AG26: size-matched | AH26: =IFERROR((AB26-AE26)/AE26,"—") | AI26: =IFERROR((S26-AE26)/AE26,"—") | AJ26: =IF(AD26>1, "⚠ HIGH SPREAD", IF(ABS(AH26)>0.5, "⚠ DELTA", "OK"))
B27: C-20-004 | C27: Riprap D50 600mm heavy - supply+place | D27: m3 | E27: 78 | F27: 147 | G27: 75 | H27: 143 | I27: 87 | J27: 165 | K27: 85 | L27: 151 | M27: 89 | N27: 189 | O27: 94 | P27: 182 | Q27: 110 | R27: 217 | S27: - | T27: - | U27: - | V27: 66.45 | W27: 85.97 | X27: 13.85 | Y27: 12.44 | Z27: 60 | AA27: =MIN(V27:Z27) | AB27: =MEDIAN(V27:Z27) | AC27: =MAX(V27:Z27) | AD27: =IFERROR((AC27-AA27)/AB27,"—") | AE27: =AVERAGE(G27,H27) | AF27: OK — sources align | AG27: size-matched | AH27: =IFERROR((AB27-AE27)/AE27,"—") | AI27: =IFERROR((S27-AE27)/AE27,"—") | AJ27: =IF(AD27>1, "⚠ HIGH SPREAD", IF(ABS(AH27)>0.5, "⚠ DELTA", "OK"))
B28: C-20-010 | C28: Sediment dewatering bag - S+I | D28: ea | E28: 1104 | F28: 1680 | G28: 1056 | H28: 1632 | I28: 1224 | J28: 1888 | K28: 1200 | L28: 1728 | M28: 1260 | N28: 2160 | O28: 1320 | P28: 2080 | Q28: 1560 | R28: 2480 | S28: 1171.5 | T28: - | U28: - | V28: 8570 | W28: 34.56 | X28: 766.65 | Y28: — | Z28: 2500 | AA28: =MIN(V28:Z28) | AB28: =MEDIAN(V28:Z28) | AC28: =MAX(V28:Z28) | AD28: =IFERROR((AC28-AA28)/AB28,"—") | AE28: =AVERAGE(G28,H28) | AF28: OK — sources align | AG28: keyword-matched | AH28: =IFERROR((AB28-AE28)/AE28,"—") | AI28: =IFERROR((S28-AE28)/AE28,"—") | AJ28: =IF(AD28>1, "⚠ HIGH SPREAD", IF(ABS(AH28)>0.5, "⚠ DELTA", "OK"))
B29: C-20-008 | C29: Silt fence heavy duty - supply+install | D29: m | E29: 17 | F29: 29 | G29: 16 | H29: 29 | I29: 18 | J29: 33 | K29: 18 | L29: 30 | M29: 19 | N29: 38 | O29: 20 | P29: 36 | Q29: 23 | R29: 43 | S29: 50 | T29: 15.16 | U29: - | V29: 22.7 | W29: 34.56 | X29: 23.4 | Y29: 10.59 | Z29: 12 | AA29: =MIN(V29:Z29) | AB29: =MEDIAN(V29:Z29) | AC29: =MAX(V29:Z29) | AD29: =IFERROR((AC29-AA29)/AB29,"—") | AE29: =AVERAGE(G29,H29) | AF29: OK — sources align | AG29: keyword-matched | AH29: =IFERROR((AB29-AE29)/AE29,"—") | AI29: =IFERROR((S29-AE29)/AE29,"—") | AJ29: =IF(AD29>1, "⚠ HIGH SPREAD", IF(ABS(AH29)>0.5, "⚠ DELTA", "OK"))
B30: C-20-009 | C30: Straw bale flow check dam - supply+install | D30: m | E30: 20 | F30: 34 | G30: 19 | H30: 33 | I30: 22 | J30: 38 | K30: 22 | L30: 35 | M30: 23 | N30: 43 | O30: 24 | P30: 42 | Q30: 29 | R30: 50 | S30: 24.5344 | T30: - | U30: - | V30: 30.75 | W30: 27.64 | X30: 27.43 | Y30: 10.59 | Z30: 40 | AA30: =MIN(V30:Z30) | AB30: =MEDIAN(V30:Z30) | AC30: =MAX(V30:Z30) | AD30: =IFERROR((AC30-AA30)/AB30,"—") | AE30: =AVERAGE(G30,H30) | AF30: OK — sources align | AG30: keyword-matched | AH30: =IFERROR((AB30-AE30)/AE30,"—") | AI30: =IFERROR((S30-AE30)/AE30,"—") | AJ30: =IF(AD30>1, "⚠ HIGH SPREAD", IF(ABS(AH30)>0.5, "⚠ DELTA", "OK"))
B31: C-20-011 | C31: Temp pump diesel submersible 8-wk rental | D31: ea | E31: 6900 | F31: 9975 | G31: 6600 | H31: 9690 | I31: 7650 | J31: 11210 | K31: 7500 | L31: 10260 | M31: 7875 | N31: 12825 | O31: 8250 | P31: 12350 | Q31: 9750 | R31: 14725 | S31: 70612.546 | T31: - | U31: - | V31: 174300 | W31: — | X31: — | Y31: — | Z31: — | AA31: — | AB31: =MEDIAN(V31:Z31) | AC31: — | AD31: — | AE31: =AVERAGE(G31,H31) | AF31: Only 1/5 bidders priced — limited market signal | AG31: category-fallback | AH31: =IFERROR((AB31-AE31)/AE31,"—") | AI31: =IFERROR((S31-AE31)/AE31,"—") | AJ31: —
A32: C. Roads/Pads
B33: C-30-005 | C33: Asphalt paving 50mm HL3 surface course | D33: m2 | E33: 41 | F33: 65 | G33: 40 | H33: 63 | I33: 46 | J33: 73 | K33: 45 | L33: 67 | M33: 47 | N33: 84 | O33: 50 | P33: 81 | Q33: 58 | R33: 96 | S33: - | T33: - | U33: - | V33: 30.6 | W33: 36.27 | X33: 19.18 | Y33: 2.3 | Z33: 20 | AA33: =MIN(V33:Z33) | AB33: =MEDIAN(V33:Z33) | AC33: =MAX(V33:Z33) | AD33: =IFERROR((AC33-AA33)/AB33,"—") | AE33: =AVERAGE(G33,H33) | AF33: OK — sources align | AG33: category-fallback | AH33: =IFERROR((AB33-AE33)/AE33,"—") | AI33: =IFERROR((S33-AE33)/AE33,"—") | AJ33: =IF(AD33>1, "⚠ HIGH SPREAD", IF(ABS(AH33)>0.5, "⚠ DELTA", "OK"))
B34: C-30-007 | C34: Equipment pad concrete 300mm slab on grade | D34: m2 | E34: 170 | F34: 278 | G34: 163 | H34: 270 | I34: 189 | J34: 313 | K34: 185 | L34: 286 | M34: 194 | N34: 358 | O34: 204 | P34: 344 | Q34: 240 | R34: 411 | S34: 947.07844 | T34: - | U34: - | V34: — | W34: — | X34: — | Y34: — | Z34: — | AA34: — | AB34: — | AC34: — | AD34: — | AE34: =AVERAGE(G34,H34) | AF34: No bidder data; SME only | AG34: no match | AH34: =IFERROR((AB34-AE34)/AE34,"—") | AI34: =IFERROR((S34-AE34)/AE34,"—") | AJ34: —
B35: C-30-006 | C35: Equipment pad granular 600mm - heavy duty | D35: m2 | E35: 46 | F35: 74 | G35: 44 | H35: 71 | I35: 51 | J35: 83 | K35: 50 | L35: 76 | M35: 52 | N35: 94 | O35: 55 | P35: 91 | Q35: 65 | R35: 108 | S35: 50 | T35: - | U35: - | V35: — | W35: — | X35: — | Y35: — | Z35: — | AA35: — | AB35: — | AC35: — | AD35: — | AE35: =AVERAGE(G35,H35) | AF35: No bidder data; SME only | AG35: no match | AH35: =IFERROR((AB35-AE35)/AE35,"—") | AI35: =IFERROR((S35-AE35)/AE35,"—") | AJ35: —
B36: C-30-008 | C36: Geotextile separation under road base - S+I | D36: m2 | E36: 3 | F36: 5 | G36: 3 | H36: 5 | I36: 3 | J36: 6 | K36: 3 | L36: 5 | M36: 3 | N36: 7 | O36: 3 | P36: 6 | Q36: 4 | R36: 8 | S36: - | T36: - | U36: - | V36: 4.9 | W36: 5.68 | X36: 10.86 | Y36: 1.4 | Z36: 5 | AA36: =MIN(V36:Z36) | AB36: =MEDIAN(V36:Z36) | AC36: =MAX(V36:Z36) | AD36: =IFERROR((AC36-AA36)/AB36,"—") | AE36: =AVERAGE(G36,H36) | AF36: OK — sources align | AG36: keyword-matched | AH36: =IFERROR((AB36-AE36)/AE36,"—") | AI36: =IFERROR((S36-AE36)/AE36,"—") | AJ36: =IF(AD36>1, "⚠ HIGH SPREAD", IF(ABS(AH36)>0.5, "⚠ DELTA", "OK"))
B37: C-30-003 | C37: Granular sub-base 300mm - supply+place+compact | D37: m2 | E37: 29 | F37: 47 | G37: 28 | H37: 46 | I37: 33 | J37: 53 | K37: 32 | L37: 49 | M37: 34 | N37: 61 | O37: 35 | P37: 58 | Q37: 42 | R37: 70 | S37: 50 | T37: - | U37: - | V37: 30.6 | W37: 36.27 | X37: 19.18 | Y37: — | Z37: 75 | AA37: =MIN(V37:Z37) | AB37: =MEDIAN(V37:Z37) | AC37: =MAX(V37:Z37) | AD37: =IFERROR((AC37-AA37)/AB37,"—") | AE37: =AVERAGE(G37,H37) | AF37: OK — sources align | AG37: category-fallback | AH37: =IFERROR((AB37-AE37)/AE37,"—") | AI37: =IFERROR((S37-AE37)/AE37,"—") | AJ37: =IF(AD37>1, "⚠ HIGH SPREAD", IF(ABS(AH37)>0.5, "⚠ DELTA", "OK"))
B38: C-30-004 | C38: Granular surface course 150mm - supply+place | D38: m2 | E38: 20 | F38: 34 | G38: 19 | H38: 33 | I38: 22 | J38: 38 | K38: 22 | L38: 35 | M38: 23 | N38: 43 | O38: 24 | P38: 42 | Q38: 29 | R38: 50 | S38: 1000 | T38: - | U38: - | V38: 30.6 | W38: 36.27 | X38: 19.18 | Y38: 2.3 | Z38: 75 | AA38: =MIN(V38:Z38) | AB38: =MEDIAN(V38:Z38) | AC38: =MAX(V38:Z38) | AD38: =IFERROR((AC38-AA38)/AB38,"—") | AE38: =AVERAGE(G38,H38) | AF38: OK — sources align | AG38: category-fallback | AH38: =IFERROR((AB38-AE38)/AE38,"—") | AI38: =IFERROR((S38-AE38)/AE38,"—") | AJ38: =IF(AD38>1, "⚠ HIGH SPREAD", IF(ABS(AH38)>0.5, "⚠ DELTA", "OK"))
B39: C-30-002 | C39: Haul road - sub-grade preparation only | D39: m2 | E39: 13 | F39: 23 | G39: 12 | H39: 22 | I39: 14 | J39: 26 | K39: 14 | L39: 24 | M39: 15 | N39: 30 | O39: 15 | P39: 29 | Q39: 18 | R39: 34 | S39: 26 | T39: - | U39: - | V39: 8.42 | W39: 7.89 | X39: 10.86 | Y39: 1.4 | Z39: 8.5 | AA39: =MIN(V39:Z39) | AB39: =MEDIAN(V39:Z39) | AC39: =MAX(V39:Z39) | AD39: =IFERROR((AC39-AA39)/AB39,"—") | AE39: =AVERAGE(G39,H39) | AF39: OK — sources align | AG39: keyword-matched | AH39: =IFERROR((AB39-AE39)/AE39,"—") | AI39: =IFERROR((S39-AE39)/AE39,"—") | AJ39: =IF(AD39>1, "⚠ HIGH SPREAD", IF(ABS(AH39)>0.5, "⚠ DELTA", "OK"))
B40: C-30-009 | C40: Road crown and ditching - motor grader finish | D40: m | E40: 5 | F40: 10 | G40: 4 | H40: 10 | I40: 5 | J40: 12 | K40: 5 | L40: 11 | M40: 5 | N40: 14 | O40: 6 | P40: 13 | Q40: 6 | R40: 16 | S40: - | T40: - | U40: - | V40: — | W40: — | X40: — | Y40: — | Z40: — | AA40: — | AB40: — | AC40: — | AD40: — | AE40: =AVERAGE(G40,H40) | AF40: No bidder data; SME only | AG40: no match | AH40: =IFERROR((AB40-AE40)/AE40,"—") | AI40: =IFERROR((S40-AE40)/AE40,"—") | AJ40: —
...

Sheet 02 Equipment Rates
A1: EQUIPMENT HOURLY RATES - Canada-wide 2026 (fully operated $/hr CAD)
A2: Hourly equipment rates by region. Anchored to Rick Q2 2026 operator intel (tandem $150/hr, wiggle wagon $200/hr). Base rates from RMM Rev 5 Sheet 06.
A3: IDENTIFICATION | D3: ATLANTIC (NL / NS) | H3: CENTRAL (ON / MB-SK) | L3: WESTERN (AB / BC) | P3: NORTHERN (YT/NWT) | R3: ANCHORS (Rick / GHD) | T3: FLEET CHARACTERISTICS | W3: NOTES
A4: Cat | B4: Equipment | C4: Size / Capacity | D4: NL Low | E4: NL High | F4: NS Low | G4: NS High | H4: ON Low | I4: ON High | J4: MB/SK Low | K4: MB/SK High | L4: AB Low | M4: AB High | N4: BC Low | O4: BC High | P4: YT Low | Q4: YT High | R4: Rick Q2 2026 | S4: GHD Goldboro implied | T4: Fuel L/hr | U4: Mob/Demob | V4: Avail % | W4: Notes
A5: HT | B5: Tandem dump truck | C5: 18-20T | D5: 129 | E5: 173 | F5: 123 | G5: 168 | H5: 143 | I5: 195 | J5: 140 | K5: 178 | L5: 147 | M5: 223 | N5: 154 | O5: 214 | P5: 182 | Q5: 256 | R5: 150 | S5: see scope rate | T5: 45-65 | U5: Required | V5: 85% | W5: Standard short-haul; operator included
A6: HT | B6: Tri-axle dump truck | C6: 25T | D6: 143 | E6: 189 | F6: 136 | G6: 184 | H6: 158 | I6: 212 | J6: 155 | K6: 194 | L6: 163 | M6: 243 | N6: 170 | O6: 234 | P6: 202 | Q6: 279 | R6: - | S6: see scope rate | T6: 55-75 | U6: Required | V6: 85% | W6: Mid-size haul; operator included
A7: HT | B7: Wiggle wagon / Super B | C7: 45T | D7: 170 | E7: 226 | F7: 163 | G7: 219 | H7: 189 | I7: 254 | J7: 185 | K7: 232 | L7: 194 | M7: 290 | N7: 204 | O7: 280 | P7: 240 | Q7: 333 | R7: 200 | S7: see scope rate | T7: 65-90 | U7: Required | V7: 80% | W7: Field confirmed Q2-2026 Rick intel
A8: HT | B8: Off-road haul truck | C8: 40-100T | D8: 294 | E8: 525 | F8: 282 | G8: 510 | H8: 326 | I8: 590 | J8: 320 | K8: 540 | L8: 336 | M8: 675 | N8: 352 | O8: 650 | P8: 416 | Q8: 775 | R8: - | S8: see scope rate | T8: 80-140 | U8: Included | V8: 85% | W8: Mining-pit haul; Komatsu/CAT
A9: EX | B9: Hydraulic excavator Cat 320 | C9: 20-25T | D9: 230 | E9: 346 | F9: 220 | G9: 337 | H9: 255 | I9: 389 | J9: 250 | K9: 356 | L9: 262 | M9: 446 | N9: 275 | O9: 429 | P9: 325 | Q9: 512 | R9: - | S9: see scope rate | T9: 18-25 | U9: Required | V9: 85% | W9: Production dig/load
A10: EX | B10: Hydraulic excavator Cat 336 | C10: 35-40T | D10: 313 | E10: 452 | F10: 299 | G10: 439 | H10: 347 | I10: 507 | J10: 340 | K10: 464 | L10: 357 | M10: 580 | N10: 374 | O10: 559 | P10: 442 | Q10: 666 | R10: - | S10: see scope rate | T10: 25-35 | U10: Required | V10: 85% | W10: Bulk earthworks / rock
A11: EX | B11: Hydraulic excavator Cat 390 | C11: 50-65T | D11: 423 | E11: 609 | F11: 405 | G11: 592 | H11: 469 | I11: 684 | J11: 460 | K11: 626 | L11: 483 | M11: 783 | N11: 506 | O11: 754 | P11: 598 | Q11: 899 | R11: - | S11: see scope rate | T11: 38-50 | U11: Required | V11: 82% | W11: Mass excavation
A12: EX | B12: Long-reach excavator | C12: 20T 18m | D12: 267 | E12: 399 | F12: 255 | G12: 388 | H12: 296 | I12: 448 | J12: 290 | K12: 410 | L12: 304 | M12: 513 | N12: 319 | O12: 494 | P12: 377 | Q12: 589 | R12: - | S12: see scope rate | T12: 18-25 | U12: Required | V12: 82% | W12: Pond, ditch, shoreline
A13: DO | B13: Track dozer Cat D6N | C13: 17T | D13: 230 | E13: 336 | F13: 220 | G13: 326 | H13: 255 | I13: 378 | J13: 250 | K13: 346 | L13: 262 | M13: 432 | N13: 275 | O13: 416 | P13: 325 | Q13: 496 | R13: - | S13: see scope rate | T13: 20-30 | U13: Required | V13: 88% | W13: Clear, rough grade, push
A14: DO | B14: Track dozer Cat D8T | C14: 37T | D14: 350 | E14: 504 | F14: 334 | G14: 490 | H14: 388 | I14: 566 | J14: 380 | K14: 518 | L14: 399 | M14: 648 | N14: 418 | O14: 624 | P14: 494 | Q14: 744 | R14: - | S14: see scope rate | T14: 35-48 | U14: Required | V14: 88% | W14: Production push, rip rock
A15: DO | B15: Track dozer Cat D10T | C15: 58T | D15: 478 | E15: 682 | F15: 458 | G15: 663 | H15: 530 | I15: 767 | J15: 520 | K15: 702 | L15: 546 | M15: 878 | N15: 572 | O15: 845 | P15: 676 | Q15: 1008 | R15: - | S15: see scope rate | T15: 50-68 | U15: Required | V15: 85% | W15: Mass earthworks / stripping
A16: GR | B16: Motor grader Cat 140M | C16: - | D16: 258 | E16: 378 | F16: 246 | G16: 367 | H16: 286 | I16: 425 | J16: 280 | K16: 389 | L16: 294 | M16: 486 | N16: 308 | O16: 468 | P16: 364 | Q16: 558 | R16: - | S16: see scope rate | T16: 18-26 | U16: Required | V16: 88% | W16: Road maint, final grade
A17: GR | B17: Motor grader Cat 16M | C17: large | D17: 331 | E17: 472 | F17: 317 | G17: 459 | H17: 367 | I17: 531 | J17: 360 | K17: 486 | L17: 378 | M17: 608 | N17: 396 | O17: 585 | P17: 468 | Q17: 698 | R17: - | S17: see scope rate | T17: 22-32 | U17: Required | V17: 88% | W17: Large platform grading
A18: CP | B18: Vib roller Cat CS56B | C18: 12T | D18: 184 | E18: 284 | F18: 176 | G18: 275 | H18: 204 | I18: 319 | J18: 200 | K18: 292 | L18: 210 | M18: 364 | N18: 220 | O18: 351 | P18: 260 | Q18: 418 | R18: - | S18: see scope rate | T18: 15-22 | U18: Required | V18: 88% | W18: 200-300mm lift compaction
A19: CP | B19: Padfoot compactor CS74B | C19: 17T | D19: 221 | E19: 326 | F19: 211 | G19: 316 | H19: 245 | I19: 366 | J19: 240 | K19: 335 | L19: 252 | M19: 418 | N19: 264 | O19: 403 | P19: 312 | Q19: 480 | R19: - | S19: see scope rate | T19: 18-26 | U19: Required | V19: 88% | W19: Cohesive soil
... A34: MI | B34: Water truck dust suppression | C34: 10,000L | D34: 147 | E34: 231 | F34: 141 | G34: 224 | H34: 163 | I34: 260 | J34: 160 | K34: 238 | L34: 168 | M34: 297 | N34: 176 | O34: 286 | P34: 208 | Q34: 341 | R34: - | S34: see scope rate | T34: 30-40 | U34: Required | V34: 90% | W34: Operator included
A36: EQUIPMENT CATEGORY KEY
A37: HT | B37: Hauling Trucks
A38: EX | B38: Excavators
A39: DO | B39: Dozers
A40: GR | B40: Motor Graders
A41: CP | B41: Compaction
A42: WL | B42: Wheel Loaders
A43: DR | B43: Drill Rigs
A44: SK | B44: Skid Steers
A45: WP | B45: Water Pumps
A46: CR | B46: Cranes
A47: MI | B47: Miscellaneous / Site Support

Sheet 03 Regional Adjustors
A1: REGIONAL ADJUSTOR FACTORS - Canada 2026
A2: Multiplier on Canada-wide BASE rate (MB/SK is baseline = 1.00 factor). Apply to RMM Rev 5 SME ranges.
A3: Code | B3: Region | C3: Factor Low | D3: Factor High | E3: Basis / Notes
A4: NL | B4: Newfoundland & Labrador | C4: 0.92 | D4: 1.05 | E4: Atlantic NL+Labrador. Tight labour pool (Stats Can Q1 2026 flagged Atlantic skill shortage); accessible coastal NL slightly above NS.
A5: NS | B5: Nova Scotia (Atlantic accessible) | C5: 0.88 | D5: 1.02 | E5: Atlantic NS - accessible drive-in. Baseline for GHD Goldboro 2026 vendor pricing. Lower than mining-civil Tier 2 baseline because no remote camp.
A6: NB | B6: New Brunswick | C6: 0.9 | D6: 1.05 | E6: New Brunswick - similar to NS. Slightly less competitive contractor pool.
A7: QC | B7: Quebec (Montreal to N. Quebec) | C7: 1.03 | D7: 1.22 | E7: Quebec - Montreal close to ON; Northern QC (Chibougamau / James Bay) major remote premium.
A8: ON | B8: Ontario (S. Ontario to N. ON) | C8: 1.02 | D8: 1.18 | E8: Greater Toronto / Ottawa baseline. Northern ON (Thunder Bay / Sudbury) similar to ON low.
A9: MBSK | B9: Manitoba / Saskatchewan (baseline) | C9: 1 | D9: 1.08 | E9: Prairies - open shop market; baseline 1.00 for this manual.
A10: AB | B10: Alberta (Edmonton to Oil Sands) | C10: 1.05 | D10: 1.35 | E10: Edmonton/Calgary mid-range; Oil Sands / Fort McMurray hits 1.35 ceiling.
A11: BC | B11: British Columbia (Metro to Interior) | C11: 1.1 | D11: 1.3 | E11: Metro Vancouver labour premium (IBEW/UA rates). Northern BC + winter factor 1.30 ceiling.
A12: YT | B12: Yukon / NWT / Nunavut (fly-in) | C12: 1.3 | D12: 1.55 | E12: Extreme remote; fly-in; northern allowances; sealift to NU coastal hits 1.55+.

Sheet 04 Vetting Workflow
A1: BIDDER VETTING WORKFLOW - using this benchmark
A2: How to use the Rate Schedule to push back on out-of-range bidder submissions.
A3: Step | B3: Action | C3: Detail
A4: 1 | B4: Issue this file with tender package | C4: Send to all bidders BEFORE they price. Makes clear what 2026 market data you're holding against their submission. Sets the tone that you have benchmark and will use it.
A5: 2 | B5: Receive bidder submissions | C5: Each bidder fills the Goldboro / equivalent template. Pull each bidder's unit rate per line item.
A6: 3 | B6: Open Tab '01 Rate Schedule' | C6: Find the corresponding canonical item. Read off the regional column matching the project location.
A7: 4 | B7: Compare bidder rate vs your regional range | C7: If bidder rate is WITHIN your regional Low-High range → accept (within market). If OUTSIDE the range → continue.
A8: 5 | B8: Check anchors before challenging | C8: If bidder rate is between your regional range AND the closest anchor (GHD Goldboro / AB UPA / bidder median from another tender) → it's defensible. If bidder rate is outside ALL anchors → flag for clarification.
A9: 6 | B9: Compose clarification letter | C9: Use template: 'Item [X], your unit rate is $[Y]. Our 2026 benchmark range for [region] is $[Low]-$[High], supported by GHD Goldboro 2026 vendor quotes at $[Z] and Goldboro C5027 bidder median at $[W]. Please confirm scope is per spec and re-submit OR provide written justification for delta.'
A10: 7 | B10: Track responses and re-level bids | C10: Build a simple deviations log. Re-level bids against normalized scope. The bidder with lowest re-leveled total + no scope drops = the right award.
A11: 8 | B11: Update this benchmark after award | C11: Once a project closes, add the awarded rate as a new anchor. The benchmark gets stronger every project.

Sheet 05 Sources & Methodology
A1: SOURCES & METHODOLOGY - Source Provenance and Data References
A2: Cite-able provenance for every figure in this workbook. Defensibility under Ausenco / NexGold / EPCM review.
A4: 1. PRIMARY 2026 DATA SOURCES
A5: Source | B5: What it is | C5: URL / File reference | D5: Used in
A6: Statistics Canada Q1 2026 BCPI | B6: Q1 2026 Building Construction Price Index release (Apr 28, 2026). Non-residential +3.6% YoY; +0.5% QoQ. Atlantic permit values +16.8%. Steel surtax impact flagged. Skilled labour shortage in Atlantic + Prairie. | C6: https://www150.statcan.gc.ca/n1/daily-quotidien/260428/dq260428b-eng.htm | D6: Sheet 03 regional context; escalation
A7: Statistics Canada BCPI dataset | B7: Quarterly BCPI by metro by building type. Live data refresh. | C7: https://www150.statcan.gc.ca/t1/tbl1/en/tv.action?pid=1810028901 | D7: Re-baseline trigger
A8: Alberta Transportation 2026 UPA | B8: Weighted average of 3 low bids on highway tenders awarded May 1, 2024 – Sep 30, 2025. 190 priced items, regional breakdown. Public dataset (XLSX). | C8: https://www.alberta.ca/system/files/custom_downloaded_images/trans-unit-price-averages.xlsx | D8: Sheet 01 AB UPA anchor column
A9: Alberta Transportation - Unit Prices & Cost Adjustments page | B9: Live diesel cost adjustment tables (rack rates, Stats Can index). | C9: https://www.alberta.ca/unit-prices-and-cost-adjustments | D9: Diesel reference
A10: BC Road Builders - Tender Report | B10: BC highway / civil tender awards (Peter's Bros, W.E. Stone, LaPrairie). Feb-Apr 2026 awards. | C10: https://www.roadbuilders.bc.ca/tender-report/ | D10: BC cross-check
A11: NRCan - Diesel Prices | B11: Weekly diesel pricing by region. Atlantic NS $2.13-$2.21/L; AB $1.68-$1.78/L; BC Metro $2.15-$2.35/L (May 2026). | C11: https://natural-resources.canada.ca/domestic-international-markets/diesel-prices | D11: Fuel cost calibration
A12: Bank of Canada - Exchange Rates | B12: USD/CAD 1.36-1.37 (May 2026). Live daily. | C12: https://www.bankofcanada.ca/rates/exchange/ | D12: FX basis for imported equipment / materials
A13: CBSA - Surtax Notices | B13: Notices 24-26 and 25-22: 25% surtax on Chinese-origin structural steel and rebar (Oct 2024 ongoing). | C13: https://www.cbsa-asfc.gc.ca/ | D13: Steel / rebar pricing risk
A14: Provincial WCB Tables | B14: WCB / WSIB / CNESST / WorkSafeBC / WorkplaceNL labourer + driller rate groups. | C14: https://www.worksafebc.com/ / https://www.wcb.ab.ca/ / https://www.wsib.ca/ etc. | D14: Burden composite
A15: CanadaBuys / MERX / SaskTenders / Manitoba Infrastructure | B15: Public procurement portals for cross-Canada tender data. | C15: https://canadabuys.canada.ca/ • https://www.merx.com/ • https://sasktenders.ca/ • https://www.gov.mb.ca/mti/contracts/bidresults.html | D15: Cross-Canada cross-check
A16: Natural Resources Canada - Mining Capex | B16: Sectoral mining capex 2024-2025 macro context. $16.3B 2024, $16.5B 2025 outlook. | C16: https://natural-resources.canada.ca/minerals-mining/mining-data-statistics-analysis/minerals-mining-publications/capital-expenditures | D16: Macro market context
A17: SEDAR+ - NI 43-101 Technical Reports | B17: Public mining feasibility study filings (Springpole, Madsen, etc.) with aggregate capex. | C17: https://www.sedarplus.ca/ | D17: Aggregate capex sanity check
A19: 2. PROJECT-SPECIFIC SOURCES (Ausenco / NexGold Goldboro FS 2026)
A20: Source | B20: What it is | C20: Where it lives | D20: Used in
A21: GHD Goldboro Project FS - Road & Pad MTO Table (Apr 14, 2026) | B21: Rates tab: 1,399 rows / 832 unique priced items. Vendor-quoted from Dexter (earthworks), Armtec (CSP culverts), Atlantic Poly Liner (geomembrane), Fontaine (sluice gates), KSB (pumps). | C21: Author file (proprietary, NDA basis) | D21: Sheet 01 'GHD Goldboro 2026' anchor column (96 of 180 items matched)
A22: GHD Goldboro Project FS - SW MTO Table (Apr 14, 2026) | B22: Stormwater MTO breakdown. Drainage and ESC scope. | C22: Author file (proprietary) | D22: Cross-ref for SWM items
A23: GHD Goldboro CAPEX-SW Estimate (Apr 14, 2026) | B23: CAPEX + OPEX line entries. Indirects, EIP factors. | C23: Author file (proprietary) | D23: Indirect calibration
A24: 107206-EB-00000-31344-201_A - C5027 GHD/Ausenco MTO (Apr 14, 2026) | B24: GHD-format Material Take-Off with WBS, commodity codes, DOR. 1,009-row MTO tab. | C24: Author file (proprietary) | D24: Sheet 01 WBS / commodity code framework reference
A25: Goldboro C5027 Bidder Submissions - Bird (April 2026) | B25: Bird Construction budgetary pricing submission on Ausenco-issued template. 835 line items / 702 priced. | C25: Author file (proprietary) | D25: Sheet 01 'Bidder Submissions' column
A26: Goldboro C5027 Bidder Submissions - Dexter (April 2026) | B26: Dexter Construction budgetary pricing. 835 line items / 673 priced. Atlantic NS specialist. | C26: Author file (proprietary) | D26: Sheet 01 'Bidder Submissions' column
A27: Goldboro C5027 Bidder Submissions - GIP (April 2026) | B27: Green Infrastructure Partners budgetary pricing. 835 line items / 670 priced. | C27: Author file (proprietary) | D27: Sheet 01 'Bidder Submissions' column
A28: Goldboro C5027 Bidder Submissions - Greenfields (April 2026) | B28: Greenfield Mining / Greenfields budgetary pricing. 835 line items / 566 priced. | C28: Author file (proprietary) | D28: Sheet 01 'Bidder Submissions' column
A29: Goldboro C5027 Bidder Submissions - Nova (April 2026) | B29: Nova Construction budgetary pricing. 835 line items / 634 priced. Atlantic NS contractor. | C29: Author file (proprietary) | D29: Sheet 01 'Bidder Submissions' column
A31: 3. AUTHOR / SME REFERENCES
A32: Source | B32: What it is | C32: Where it lives | D32: Used in
A33: RMM Rev 5 Full Manual (RMM-CIVIL-CANADA-2026-MANUAL-REV5.xlsx) | B33: Author's full 28-tab estimating standard: crews, labour, equipment, build-ups, indirects, escalation lanes, productivity factors, regional matrix, burden composite, Goldboro overlay tab, web sources tab. | C33: Sister file in same folder (RMM-CIVIL-CANADA-2026-MANUAL-REV5.xlsx) | D33: Methodology reference; this benchmark is operational distillation
A34: Rick Miller Q2 2026 Market Intel - operator anchors | B34: Tandem dump truck $150/hr; 45T wiggle wagon $200/hr; crushing 'through the roof' = Rev 5 reset $18-$45/t on-site, $45-$70/t trucked-in. | C34: Author's own field intelligence | D34: Sheet 01 'Rick Anchor' column; Sheet 02 Equipment Rates
A35: Ausenco go-by Q2-2020 | B35: EPCM benchmark estimator baseline that RMM Rev 5 escalated to 2026. | C35: Author's reference (not for redistribution) | D35: Sheet 01 base rates pre-escalation
A43: 4. METHODOLOGY NOTES
A44: Aspect | B44: Methodology
A45: BASE RATE SOURCE | B45: Each canonical scope item carries a Canada-wide base low/high range drawn from RMM Rev 5 Sheet 08 SoR Master. Base = MB/SK baseline.
A46: REGIONAL ADJUSTMENT | B46: Base rate multiplied by regional factor per Sheet 03: NL 0.92-1.05; NS 0.88-1.02; ON 1.02-1.18; MB/SK 1.00-1.08; AB 1.05-1.35; BC 1.10-1.30; YT/NWT 1.30-1.55.
A47: GHD GOLDBORO MATCHING | B47: Item descriptions keyword-matched (≥2 token overlap) against GHD Goldboro 832-item priced list. Where match found, GHD unit capex shown as anchor.
A48: BIDDER MATCHING | B48: Item descriptions keyword-matched (≥2 token overlap) against each of 5 bidders' MTO Earthworks submissions. Per-bidder median of top-3 matching items reported. Bidder Min / Median / Max computed across all 5 bidders' matched values.
A49: AB UPA MATCHING | B49: Narrow keyword match against ~12 Alberta UPA items where the description is unambiguously equivalent (e.g. CSP culvert 900mm, Granular base course, Asphalt Superpave).
A50: RICK ANCHOR | B50: Sparse population - only where author has provided specific Q2 2026 datapoints. Currently: crushing items (4 lines), tandem $150/hr, wiggle wagon $200/hr.
...

Sheet 06 Coverage Summary
A1: COVERAGE BY SECTION
A2: How many items have real anchor data vs SME-only - confidence tier per section.
A3: Section | B3: Items | C3: GHD Anchor | D3: Bidder Data | E3: Confidence
A4: A. Earthworks | B4: 15 | C4: 11 | D4: 13 | E4: HIGH
A5: B. Water Mgmt | B5: 10 | C5: 8 | D5: 9 | E5: HIGH
A6: C. Roads/Pads | B6: 8 | C6: 5 | D6: 4 | E6: MED
A7: D. WRSA/TMF | B7: 8 | C7: 6 | D7: 5 | E7: MED
A8: E. Drainage/Culverts | B8: 15 | C8: 11 | D8: 7 | E8: MED
A9: F. Concrete | B9: 5 | C9: 3 | D9: 1 | E9: MED
A10: G. Steel | B10: 8 | C10: 4 | D10: 3 | E10: MED
A11: H. Closure | B11: 4 | C11: 3 | D11: 2 | E11: MED
A12: I. Blasting | B12: 4 | C12: 2 | D12: 1 | E12: MED
A13: J. Dewatering | B13: 5 | C13: 4 | D13: 1 | E13: MED
A14: K. Buried Services | B14: 7 | C14: 6 | D14: 2 | E14: MED
A15: L. Concrete Paving | B15: 3 | C15: 1 | D15: 1 | E15: MED
... A28: Y. Hydraulic | B28: 9 | C28: 2 | D28: 2 | E28: LOW (SME only)

Sheet 07 Project Pricing
B2: PROJECT PRICING WORKSHEET - Quantities times Recommended Rates
B3: Operational rollup tool. Enter project name, region, and quantities. Workbook returns Owner Opinion of Probable Cost at Recommended 2026 $/UOM rates from Sheet 01. Paste bidder unit rates alongside to see direct delta per line item and at project total. Use to set the owner estimate before issuing tender and to evaluate bid envelope after submissions arrive.
B5: Project: | C5: [Enter project - e.g. Goldboro C5027 Civil, Green Bay Civil Package, Goderich Underground] | G5: Region: | H5: [Pick: NL / NS / NB / QC / ON / MB-SK / AB / BC / YT-NWT]
B6: Bidder: | C6: [Enter bidder name - or leave blank for owner estimate only] | G6: Date: | H6: Q2 2026
B8: Code | C8: Description | D8: UOM | E8: Qty | F8: REC $/UOM | G8: Owner Total at REC | H8: Bidder $/UOM | I8: Bidder Total | J8: Delta %
B9: A. Earthworks
B10: C-10-004 | C10: Backfill Type 1 (<250mm) - spread and compact | D10: m3 | E10: 0 | F10: ='01 Rate Schedule'!Y6 | G10: =IF(ISNUMBER(F10),E10*F10,0) | H10: 0 | I10: =E10*H10 | J10: =IF(AND(ISNUMBER(F10),F10>0,ISNUMBER(H10),H10>0),(H10-F10)/F10,"")
B11: C-10-005 | C11: Backfill Type 2 (<100mm) - spread and compact | D11: m3 | E11: 0 | F11: ='01 Rate Schedule'!Y7 | G11: =IF(ISNUMBER(F11),E11*F11,0) | H11: 0 | I11: =E11*H11 | J11: =IF(AND(ISNUMBER(F11),F11>0,ISNUMBER(H11),H11>0),(H11-F11)/F11,"")
B12: C-10-006 | C12: Backfill Type 3 engineered - spread and compact | D12: m3 | E12: 0 | F12: ='01 Rate Schedule'!Y8 | G12: =IF(ISNUMBER(F12),E12*F12,0) | H12: 0 | I12: =E12*H12 | J12: =IF(AND(ISNUMBER(F12),F12>0,ISNUMBER(H12),H12>0),(H12-F12)/F12,"")
B13: C-10-003 | C13: Backfill common - spread and compact | D13: m3 | E13: 0 | F13: ='01 Rate Schedule'!Y9 | G13: =IF(ISNUMBER(F13),E13*F13,0) | H13: 0 | I13: =E13*H13 | J13: =IF(AND(ISNUMBER(F13),F13>0,ISNUMBER(H13),H13>0),(H13-F13)/F13,"")
B14: C-10-014 | C14: Cut-fill balanced earthworks - large-scale | D14: m3 | E14: 0 | F14: ='01 Rate Schedule'!Y10 | G14: =IF(ISNUMBER(F14),E14*F14,0) | H14: 0 | I14: =E14*H14 | J14: =IF(AND(ISNUMBER(F14),F14>0,ISNUMBER(H14),H14>0),(H14-F14)/F14,"")
B15: C-10-016 | C15: Drill and blast holes only - excavation separate | D15: m3 | E15: 0 | F15: ='01 Rate Schedule'!Y11 | G15: =IF(ISNUMBER(F15),E15*F15,0) | H15: 0 | I15: =E15*H15 | J15: =IF(AND(ISNUMBER(F15),F15>0,ISNUMBER(H15),H15>0),(H15-F15)/F15,"")
B16: C-10-002 | C16: Excavation common soil - load + haul 1-3 km | D16: m3 | E16: 0 | F16: ='01 Rate Schedule'!Y12 | G16: =IF(ISNUMBER(F16),E16*F16,0) | H16: 0 | I16: =E16*H16 | J16: =IF(AND(ISNUMBER(F16),F16>0,ISNUMBER(H16),H16>0),(H16-F16)/F16,"")
B17: C-10-009 | C17: Granular A base (<19mm) - supply+place+compact | D17: m3 | E17: 0 | F17: ='01 Rate Schedule'!Y13 | G17: =IF(ISNUMBER(F17),E17*F17,0) | H17: 0 | I17: =E17*H17 | J17: =IF(AND(ISNUMBER(F17),F17>0,ISNUMBER(H17),H17>0),(H17-F17)/F17,"")
B18: C-10-010 | C18: Granular B sub-base (<75mm) - supply+place+compact | D18: m3 | E18: 0 | F18: ='01 Rate Schedule'!Y14 | G18: =IF(ISNUMBER(F18),E18*F18,0) | H18: 0 | I18: =E18*H18 | J18: =IF(AND(ISNUMBER(F18),F18>0,ISNUMBER(H18),H18>0),(H18-F18)/F18,"")
B19: C-10-008 | C19: Overburden strip - doze + rip + stockpile | D19: m3 | E19: 0 | F19: ='01 Rate Schedule'!Y15 | G19: =IF(ISNUMBER(F19),E19*F19,0) | H19: 0 | I19: =E19*H19 | J19: =IF(AND(ISNUMBER(F19),F19>0,ISNUMBER(H19),H19>0),(H19-F19)/F19,"")
B20: C-10-007 | C20: Rock excavation - blasted and loaded to truck | D20: m3 | E20: 0 | F20: ='01 Rate Schedule'!Y16 | G20: =IF(ISNUMBER(F20),E20*F20,0) | H20: 0 | I20: =E20*H20 | J20: =IF(AND(ISNUMBER(F20),F20>0,ISNUMBER(H20),H20>0),(H20-F20)/F20,"")
B21: C-10-011 | C21: Sand bedding layer - supply+place+compact | D21: m3 | E21: 0 | F21: ='01 Rate Schedule'!Y17 | G21: =IF(ISNUMBER(F21),E21*F21,0) | H21: 0 | I21: =E21*H21 | J21: =IF(AND(ISNUMBER(F21),F21>0,ISNUMBER(H21),H21>0),(H21-F21)/F21,"")
... B24: C-10-012 | C24: Topsoil placement - supply+spread | D24: m3 | E24: 0 | F24: ='01 Rate Schedule'!Y20 | G24: =IF(ISNUMBER(F24),E24*F24,0) | H24: 0 | I24: =E24*H24 | J24: =IF(AND(ISNUMBER(F24),F24>0,ISNUMBER(H24),H24>0),(H24-F24)/F24,"")
B25: B. Water Mgmt
B26: C-20-005 | C26: Energy dissipator riprap - full S+P | D26: m3 | E26: 0 | F26: ='01 Rate Schedule'!Y22 | G26: =IF(ISNUMBER(F26),E26*F26,0) | H26: 0 | I26: =E26*H26 | J26: =IF(AND(ISNUMBER(F26),F26>0,ISNUMBER(H26),H26>0),(H26-F26)/F26,"")
B27: C-20-006 | C27: Geotextile 10oz non-woven cushion - S+I | D27: m2 | E27: 0 | F27: ='01 Rate Schedule'!Y23 | G27: =IF(ISNUMBER(F27),E27*F27,0) | H27: 0 | I27: =E27*H27 | J27: =IF(AND(ISNUMBER(F27),F27>0,ISNUMBER(H27),H27>0),(H27-F27)/F27,"")
B28: C-20-007 | C28: Geotextile 6oz non-woven separator - S+I | D28: m2 | E28: 0 | F28: ='01 Rate Schedule'!Y24 | G28: =IF(ISNUMBER(F28),E28*F28,0) | H28: 0 | I28: =E28*H28 | J28: =IF(AND(ISNUMBER(F28),F28>0,ISNUMBER(H28),H28>0),(H28-F28)/F28,"")
B29: C-20-002 | C29: Riprap D50 150mm entrance/exit - supply+place | D29: m3 | E29: 0 | F29: ='01 Rate Schedule'!Y25 | G29: =IF(ISNUMBER(F29),E29*F29,0) | H29: 0 | I29: =E29*H29 | J29: =IF(AND(ISNUMBER(F29),F29>0,ISNUMBER(H29),H29>0),(H29-F29)/F29,"")
B30: C-20-003 | C30: Riprap D50 300mm - supply+place | D30: m3 | E30: 0 | F30: ='01 Rate Schedule'!Y26 | G30: =IF(ISNUMBER(F30),E30*F30,0) | H30: 0 | I30: =E30*H30 | J30: =IF(AND(ISNUMBER(F30),F30>0,ISNUMBER(H30),H30>0),(H30-F30)/F30,"")
B31: C-20-004 | C31: Riprap D50 600mm heavy - supply+place | D31: m3 | E31: 0 | F31: ='01 Rate Schedule'!Y27 | G31: =IF(ISNUMBER(F31),E31*F31,0) | H31: 0 | I31: =E31*H31 | J31: =IF(AND(ISNUMBER(F31),F31>0,ISNUMBER(H31),H31>0),(H31-F31)/F31,"")
B32: C-20-010 | C32: Sediment dewatering bag - S+I | D32: ea | E32: 0 | F32: ='01 Rate Schedule'!Y28 | G32: =IF(ISNUMBER(F32),E32*F32,0) | H32: 0 | I32: =E32*H32 | J32: =IF(AND(ISNUMBER(F32),F32>0,ISNUMBER(H32),H32>0),(H32-F32)/F32,"")
B33: C-20-008 | C33: Silt fence heavy duty - supply+install | D33: m | E33: 0 | F33: ='01 Rate Schedule'!Y29 | G33: =IF(ISNUMBER(F33),E33*F33,0) | H33: 0 | I33: =E33*H33 | J33: =IF(AND(ISNUMBER(F33),F33>0,ISNUMBER(H33),H33>0),(H33-F33)/F33,"")
B34: C-20-009 | C34: Straw bale flow check dam - supply+install | D34: m | E34: 0 | F34: ='01 Rate Schedule'!Y30 | G34: =IF(ISNUMBER(F34),E34*F34,0) | H34: 0 | I34: =E34*H34 | J34: =IF(AND(ISNUMBER(F34),F34>0,ISNUMBER(H34),H34>0),(H34-F34)/F34,"")
B35: C-20-011 | C35: Temp pump diesel submersible 8-wk rental | D35: ea | E35: 0 | F35: ='01 Rate Schedule'!Y31 | G35: =IF(ISNUMBER(F35),E35*F35,0) | H35: 0 | I35: =E35*H35 | J35: =IF(AND(ISNUMBER(F35),F35>0,ISNUMBER(H35),H35>0),(H35-F35)/F35,"")
B36: C. Roads/Pads
B37: C-30-005 | C37: Asphalt paving 50mm HL3 surface course | D37: m2 | E37: 0 | F37: ='01 Rate Schedule'!Y33 | G37: =IF(ISNUMBER(F37),E37*F37,0) | H37: 0 | I37: =E37*H37 | J37: =IF(AND(ISNUMBER(F37),F37>0,ISNUMBER(H37),H37>0),(H37-F37)/F37,"")
B38: C-30-007 | C38: Equipment pad concrete 300mm slab on grade | D38: m2 | E38: 0 | F38: ='01 Rate Schedule'!Y34 | G38: =IF(ISNUMBER(F38),E38*F38,0) | H38: 0 | I38: =E38*H38 | J38: =IF(AND(ISNUMBER(F38),F38>0,ISNUMBER(H38),H38>0),(H38-F38)/F38,"")
B39: C-30-006 | C39: Equipment pad granular 600mm - heavy duty | D39: m2 | E39: 0 | F39: ='01 Rate Schedule'!Y35 | G39: =IF(ISNUMBER(F39),E39*F39,0) | H39: 0 | I39: =E39*H39 | J39: =IF(AND(ISNUMBER(F39),F39>0,ISNUMBER(H39),H39>0),(H39-F39)/F39,"")
B40: C-30-008 | C40: Geotextile separation under road base - S+I | D40: m2 | E40: 0 | F40: ='01 Rate Schedule'!Y36 | G40: =IF(ISNUMBER(F40),E40*F40,0) | H40: 0 | I40: =E40*H40 | J40: =IF(AND(ISNUMBER(F40),F40>0,ISNUMBER(H40),H40>0),(H40-F40)/F40,"")
B41: C-30-003 | C41: Granular sub-base 300mm - supply+place+compact | D41: m2 | E41: 0 | F41: ='01 Rate Schedule'!Y37 | G41: =IF(ISNUMBER(F41),E41*F41,0) | H41: 0 | I41: =E41*H41 | J41: =IF(AND(ISNUMBER(F41),F41>0,ISNUMBER(H41),H41>0),(H41-F41)/F41,"")
B42: C-30-004 | C42: Granular surface course 150mm - supply+place | D42: m2 | E42: 0 | F42: ='01 Rate Schedule'!Y38 | G42: =IF(ISNUMBER(F42),E42*F42,0) | H42: 0 | I42: =E42*H42 | J42: =IF(AND(ISNUMBER(F42),F42>0,ISNUMBER(H42),H42>0),(H42-F42)/F42,"")
B43: C-30-002 | C43: Haul road - sub-grade preparation only | D43: m2 | E43: 0 | F43: ='01 Rate Schedule'!Y39 | G43: =IF(ISNUMBER(F43),E43*F43,0) | H43: 0 | I43: =E43*H43 | J43: =IF(AND(ISNUMBER(F43),F43>0,ISNUMBER(H43),H43>0),(H43-F43)/F43,"")
B44: C-30-009 | C44: Road crown and ditching - motor grader finish | D44: m | E44: 0 | F44: ='01 Rate Schedule'!Y40 | G44: =IF(ISNUMBER(F44),E44*F44,0) | H44: 0 | I44: =E44*H44 | J44: =IF(AND(ISNUMBER(F44),F44>0,ISNUMBER(H44),H44>0),(H44-F44)/F44,"")
B45: D. WRSA/TMF
...

Sheet 08 Data Integrity QC
B2: DATA INTEGRITY QC - Rates Flagged for Source Review
B3: Rates where GHD anchor or Bidder Med disagrees with Recommended by more than 100% - typically indicates unit-of-measure mismatch or scope misalignment between sources. These are the items to review BEFORE issuing this benchmark externally. Once UOM/scope is reconciled, either the Recommended rate stays as-is (the bidder/GHD source priced different scope) or the Recommended rate is revised.
B5: Code | C5: Description | D5: UOM | E5: Recommended | F5: GHD Δ % | G5: Bidder Δ % | H5: Likely Issue
B6: C-10-003 | C6: Backfill common - spread and compact | D6: m3 | E6: 24 | F6: 2.5416667 | G6: 1.1641667 | H6: GHD scope mismatch - verify scope inclusions
B7: C-10-016 | C7: Drill and blast holes only - excavation separate | D7: m3 | E7: 51.5 | F7: 286.37864 | G7: -0.7776699 | H7: GHD likely different UOM (per-hole vs $/m3)
B8: C-20-008 | C8: Silt fence heavy duty - supply+install | D8: m | E8: 22.5 | F8: 1.2222222 | G8: 443.44444 | H8: GHD scope mismatch - verify scope inclusions
B9: C-20-009 | C9: Straw bale flow check dam - supply+install | D9: m | E9: 26 | F9: -0.056369231 | G9: 383.61538 | H9: Bidder priced different scope - clarify
B10: C-20-011 | C10: Temp pump diesel submersible 8-wk rental | D10: ea | E10: 8145 | F10: 7.6694348 | G10: - | H10: GHD likely different UOM (per-hole vs $/m3)
B11: C-30-007 | C11: Equipment pad concrete 300mm slab on grade | D11: m2 | E11: 216.5 | F11: 3.3744963 | G11: 62.100323 | H11: GHD scope mismatch - verify scope inclusions
B12: C-30-004 | C12: Granular surface course 150mm - supply+place | D12: m2 | E12: 26 | F12: 37.461538 | G12: 0.80115385 | H12: GHD likely different UOM (per-hole vs $/m3)
B13: C-40-008 | C13: Protective cover soil over liner - place+compact | D13: m3 | E13: 36 | F13: 1421.9767 | G13: 0.14583333 | H13: GHD likely different UOM (per-hole vs $/m3)
B14: C-50-016 | C14: Discharge trench clear stone - supply+place | D14: m3 | E14: 148.5 | F14: -0.14997037 | G14: 1.7946128 | H14: Bidder scope likely different - verify
B15: C-50-010 | C15: HDPE 100mm DR11 buried - excav+install+BF | D15: m | E15: 340.5 | F15: 278.4849 | G15: 0.0039941263 | H15: GHD likely different UOM (per-hole vs $/m3)
B16: C-50-011 | C16: HDPE 150mm DR11 above grade + insulation | D16: m | E16: 278.5 | F16: 0.016976661 | G16: 1.3812208 | H16: Bidder scope likely different - verify
B17: C-50-012 | C17: HDPE 200mm DR11 above grade + insulation | D17: m | E17: 324 | F17: -0.12583951 | G17: 1.046821 | H17: Bidder scope likely different - verify
B18: C-50-013 | C18: HDPE 600mm DR17 above grade + insulation | D18: m | E18: 311.5 | F18: -0.090760835 | G18: 1.1289567 | H18: Bidder scope likely different - verify
B19: C-60-006 | C19: Rebar Grade 400 - supply+install | D19: tonne | E19: 4820 | F19: -0.79253112 | G19: 1.0746888 | H19: Bidder scope likely different - verify
B20: C-70-005 | C20: Steel grating 32x4.8mm - supply+install | D20: m2 | E20: 673 | F20: 0.4858841 | G20: 13.858841 | H20: Bidder priced different scope - clarify
B21: C-80-002 | C21: Riprap closure cap D50 300mm - supply+place | D21: m3 | E21: 116 | F21: 713.65407 | G21: -0.079827586 | H21: GHD likely different UOM (per-hole vs $/m3)
B22: C-80-004 | C22: Topsoil replacement - spread+seed | D22: m2 | E22: 8 | F22: 3749 | G22: - | H22: GHD likely different UOM (per-hole vs $/m3)
B23: B-01-002 | C23: Drill blast hole 89-115mm - rotary drill | D23: m | E23: 34 | F23: 434.29412 | G23: - | H23: GHD likely different UOM (per-hole vs $/m3)
B24: B-01-003 | C24: Rock blasting - drill+charge+blast+clear (all-in) | D24: m3 | E24: 63.5 | F24: 232.07087 | G24: 5.8110236 | H24: GHD likely different UOM (per-hole vs $/m3)
B25: B-02-004 | C25: Forcemain HDPE 150mm buried - S+I | D25: m | E25: 355 | F25: 267.06932 | G25: - | H25: GHD likely different UOM (per-hole vs $/m3)
B26: B-02-005 | C26: Forcemain HDPE 200mm buried - S+I | D26: m | E26: 422 | F26: 224.50855 | G26: - | H26: GHD likely different UOM (per-hole vs $/m3)
B27: B-03-007 | C27: Gate valve 150mm buried - S+I | D27: ea | E27: 2753 | F27: 147.71225 | G27: - | H27: GHD likely different UOM (per-hole vs $/m3)
B28: B-03-004 | C28: Sanitary sewer PVC 150mm buried - S+I | D28: m | E28: 432 | F28: 1.6851852 | G28: - | H28: GHD scope mismatch - verify scope inclusions
B29: B-07-005 | C29: Shotcrete with wire mesh 100mm - S+A | D29: m2 | E29: 200 | F29: 36.217795 | G29: - | H29: GHD likely different UOM (per-hole vs $/m3)
B30: B-07-003 | C30: Wire mesh rockfall protection - supply+pin | D30: m2 | E30: 89.5 | F30: 82.168257 | G30: - | H30: GHD likely different UOM (per-hole vs $/m3)
B31: U-10-012 | C31: Stope backfill - paste fill placement | D31: m3 | E31: 68.5 | F31: 3.9861314 | G31: -0.63094891 | H31: GHD scope mismatch - verify scope inclusions
B32: T-20-012 | C32: Spillway - concrete-lined emergency overflow | D32: m2 | E32: 580.5 | F32: 222.94488 | G32: -0.98156761 | H32: GHD likely different UOM (per-hole vs $/m3)
B33: H-30-006 | C33: Drain rock cover 300mm - supply+place | D33: m3 | E33: 72.5 | F33: -0.75862069 | G33: 1.0122759 | H33: Bidder scope likely different - verify
B34: H-30-001 | C34: Pad sub-grade prep - cut/fill/compact 95% Proctor | D34: m2 | E34: 24.5 | F34: 2.4693878 | G34: -0.89714286 | H34: GHD scope mismatch - verify scope inclusions
B35: H-30-009 | C35: Solution piping HDPE 200mm - S+I | D35: m | E35: 357 | F35: 2.912605 | G35: - | H35: GHD scope mismatch - verify scope inclusions
B36: P-40-002 | C36: Mill foundation - ball mill | D36: m3 | E36: 2951 | F36: 1805.3679 | G36: - | H36: GHD likely different UOM (per-hole vs $/m3)
B37: P-40-007 | C37: Ore stockpile reclaim tunnel | D37: m | E37: 24240 | F37: 155.76568 | G37: - | H37: GHD likely different UOM (per-hole vs $/m3)
B38: P-40-003 | C38: Primary crusher foundation - pier+mat | D38: m3 | E38: 3703 | F38: 2024.3848 | G38: 230.29895 | H38: GHD likely different UOM (per-hole vs $/m3)
B39: P-40-011 | C39: Process building slab on grade 250mm | D39: m2 | E39: 231.5 | F39: 3.0910516 | G39: - | H39: GHD scope mismatch - verify scope inclusions
B40: SP-50-003 | C40: HDPE slurry pipe 250mm SDR 11 - supply | D40: m | E40: 207.5 | F40: 1.0499432 | G40: - | H40: GHD scope mismatch - verify scope inclusions
B41: EL-70-005 | C41: Substation control building slab + foundation | D41: m2 | E41: 355 | F41: 4224.3521 | G41: - | H41: GHD likely different UOM (per-hole vs $/m3)
B43: TOTAL FLAGGED: 36 rates. ACTION: Before issuing this benchmark externally with a tender package, review these line items for UOM/scope alignment. Once verified, either confirm the Recommended rate stays right (bidder/GHD scope is different) or revise the Recommended rate. The benchmark gets stronger every project as scope mismatches are resolved.
